Workbook

Sheet Sprint 1
A1: Project name: | C1: Ứng dụng đặt phòng thông minh với AI Search Assistant và gợi ý theo hành vi người dùng | F1: Kết thúc đúng hạn
A2: Module name: | C2: Sprint 1 | F2: Muộn
A3: Start date: | C3: 45969 | F3: Trước thời hạn
A4: End date: | C4: 22/11/2025
B6: SPRINT 1 REPORT
B7: No | C7: Thành viên | D7: Thực tế | E7: Ước tính
B8: 1 | C8: Ngô Văn Giỏi | D8: =SUMIF($E$16:$F$88,"Thành",$G$16:$G$88)+SUMIF($E$16:$F$88,"All team",$G$16:$G$88)/5+SUMIF($E$16:$F$88,"Thành,Mạnh",$G$16:$G$88)/2 -> 10.8 | E8: =SUMIF($E$16:$F$88,"Thành",$H$16:$H$88)+SUMIF($E$16:$F$88,"All team",$H$16:$H$88)/5+SUMIF($E$16:$F$88,"Thành,Mạnh",$H$16:$H$88)/2 -> 11.6
B9: 2 | C9: Nguyễn Ngọc Sơn | D9: =SUMIF($E$16:$F$88,"Mạnh",$G$16:$G$88)+SUMIF($E$16:$F$88,"All team",$G$16:$G$88)/5+SUMIF($E$16:$F$88,"Thành,Mạnh",$G$16:$G$88)/2+SUMIF($E$16:$F$88,"Mạnh,Phương",$G$16:$G$88)/2+SUMIF($E$16:$F$88,"Mạnh,Lộc,Phương,Hoàng",$G$16:$G$88)/4 -> 10.8 | E9: =SUMIF($E$16:$F$88,"Mạnh",$H$16:$H$88)+SUMIF($E$16:$F$88,"All team",$H$16:$H$88)/5+SUMIF($E$16:$F$88,"Thành,Mạnh",$H$16:$H$88)/2+SUMIF($E$16:$F$88,"Mạnh,Phương",$H$16:$H$88)/2+SUMIF($E$16:$F$88,"Mạnh,Lộc,Phương,Hoàng",$H$16:$H$88)/4 -> 11.6
B10: 3 | C10: Nguyễn Thanh Long | D10: =SUMIF($E$16:$F$88,"Phương",$G$16:$G$88)+SUMIF($E$16:$F$88,"All team",$G$16:$G$88)/5+SUMIF($E$16:$F$88,"Mạnh,Phương",$G$16:$G$88)/2+SUMIF($E$16:$F$88,"Mạnh,Lộc,Phương,Hoàng",$G$16:$G$88)/4 -> 10.8 | E10: =SUMIF($E$16:$F$88,"Phương",$H$16:$H$88)+SUMIF($E$16:$F$88,"All team",$H$16:$H$88)/5+SUMIF($E$16:$F$88,"Mạnh,Phương",$H$16:$H$88)/2+SUMIF($E$16:$F$88,"Mạnh,Lộc,Phương,Hoàng",$H$16:$H$88)/4 -> 11.6
B11: 4 | C11: Nguyễn Thanh Long | D11: =SUMIF($E$16:$F$88,"Lộc",$G$16:$G$88)+SUMIF($E$16:$F$88,"All team",$G$16:$G$88)/5+SUMIF($E$16:$F$88,"Mạnh,Lộc,Phương,Hoàng",$G$16:$G$88)/4 -> 10.8 | E11: =SUMIF($E$16:$F$88,"Lộc",$H$16:$H$88)+SUMIF($E$16:$F$88,"All team",$H$16:$H$88)/5+SUMIF($E$16:$F$88,"Mạnh,Lộc,Phương,Hoàng",$H$16:$H$88)/4 -> 11.6
B12: 5 | C12: Nguyễn Phước Thanh Tuấn | D12: =SUMIF($E$16:$F$88,"Hoàng",$G$16:$G$88)+SUMIF($E$16:$F$88,"All team",$G$16:$G$88)/5+SUMIF($E$16:$F$88,"Mạnh,Lộc,Phương,Hoàng",$G$16:$G$88)/4 -> 10.8 | E12: =SUMIF($E$16:$F$88,"Hoàng",$H$16:$H$88)+SUMIF($E$16:$F$88,"All team",$H$16:$H$88)/5+SUMIF($E$16:$F$88,"Mạnh,Lộc,Phương,Hoàng",$H$16:$H$88)/4 -> 11.6
B13: Tổng | D13: =SUM(D8:D12) -> 54 | E13: =SUM(E8:E12) -> 58
W14: *
A15: Sprint | B15: Compoment | C15: Task name | E15: Responsible Member | G15: Thực tế | H15: Ước tính | I15: 45880 | J15: 45911 | K15: 45941 | L15: 45972 | M15: 46002 | N15: 13/11/2025 | O15: 14/11/2025 | P15: 15/11/2025 | Q15: 16/11/2025 | R15: 17/11/2025 | S15: 18/11/2025 | T15: 19/11/2025 | U15: 20/11/2025 | V15: 21/11/2025 | W15: 22/11/2025
A16: Sprint 1 | B16: Họp kế hoạch Sprint | E16: All team | G16: =H16-I16 -> 10 | H16: 10 | I16: 0 | J16: 0 | K16: 0 | L16: 0 | M16: 0 | N16: 0 | O16: 0 | P16: 0 | Q16: 0 | R16: 0 | S16: 0 | T16: 0 | U16: 0 | V16: 0 | W16: 0
B17: Tạo Sprint Backlog 1 | E17: All team | G17: 4 | H17: 4 | I17: 4 | J17: 0 | K17: 0 | L17: 0 | M17: 0 | N17: 0 | O17: 0 | P17: 0 | Q17: 0 | R17: 0 | S17: 0 | T17: 0 | U17: 0 | V17: 0 | W17: 0
B18: Tạo tài liệu kiểm thử cho Sprint | E18: All team | G18: =H18-K18 -> 4 | H18: 4 | I18: 4 | J18: 4 | K18: 0 | L18: 0 | M18: 0 | N18: 0 | O18: 0 | P18: 0 | Q18: 0 | R18: 0 | S18: 0 | T18: 0 | U18: 0 | V18: 0 | W18: 0
B19: User interface design | C19: Giao diện đăng nhập | E19: Tuấn | G19: 1 | H19: 1 | I19: 1 | J19: 1 | K19: 1 | L19: 0 | M19: 0 | N19: 0 | O19: 0 | P19: 0 | Q19: 0 | R19: 0 | S19: 0 | T19: 0 | U19: 0 | V19: 0 | W19: 0
C20: Giao diện đăng xuất | E20: Tuấn | G20: 1 | H20: 1 | I20: 1 | J20: 1 | K20: 1 | L20: 0 | M20: 0 | N20: 0 | O20: 0 | P20: 0 | Q20: 0 | R20: 0 | S20: 0 | T20: 0 | U20: 0 | V20: 0 | W20: 0
C21: Giao diện Đăng ký Tài Khoản | E21: Sơn | G21: 2 | H21: 1 | I21: 1 | J21: 1 | K21: 1 | L21: 0 | M21: 0 | N21: 0 | O21: 0 | P21: 0 | Q21: 0 | R21: 0 | S21: 0 | T21: 0 | U21: 0 | V21: 0 | W21: 0
L22: 1
C23: Giao diện Tìm Kiếm Khách Sạn | E23: Long | G23: 1 | H23: 1 | I23: 1 | J23: 1 | K23: 1 | L23: 0 | M23: 0 | N23: 0 | O23: 0 | P23: 0 | Q23: 0 | R23: 0 | S23: 0 | T23: 0 | U23: 0 | V23: 0 | W23: 0
C24: Giao diện Xem Chi Tiết Khách Sạn | E24: Long | G24: 1 | H24: 1 | I24: 1 | J24: 1 | K24: 1 | L24: 1 | M24: 0 | N24: 0 | O24: 0 | P24: 0 | Q24: 0 | R24: 0 | S24: 0 | T24: 0 | U24: 0 | V24: 0 | W24: 0
C25: Giao diện Đổi mật khẩu | E25: Toàn | G25: 1 | H25: 1 | I25: 1 | J25: 1 | K25: 1 | L25: 1 | M25: 0 | N25: 0 | O25: 0 | P25: 0 | Q25: 0 | R25: 0 | S25: 0 | T25: 0 | U25: 0 | V25: 0 | W25: 0
C26: Giao diện người dùng | E26: Toàn | G26: 1 | H26: 1 | I26: 1 | J26: 1 | K26: 1 | L26: 1 | M26: 1 | N26: 0 | O26: 0 | P26: 0 | Q26: 0 | R26: 0 | S26: 0 | T26: 0 | U26: 0 | V26: 0 | W26: 0
C27: Giao diện phân quyền | E27: Giỏi | G27: 1 | H27: 1 | I27: 1 | J27: 1 | K27: 1 | L27: 1 | M27: 1 | N27: 0 | O27: 0 | P27: 0 | Q27: 0 | R27: 0 | S27: 0 | T27: 0 | U27: 0 | V27: 0 | W27: 0
C28: Review all user interfaces of sprint 1 | E28: All team | G28: =H28+N29 -> 10 | H28: 10 | I28: 10 | J28: 10 | K28: 10 | L28: 10 | M28: 10 | N28: 10 | O28: 10 | P28: 0 | Q28: 0 | R28: 0 | S28: 0 | T28: 0 | U28: 0 | V28: 0 | W28: 0
J29: 2 | O29: -4
B30: Design test case | C30: Thiết kế trường kiểm thử cho đăng nhập | E30: Tuấn | G30: 1 | H30: 1 | I30: 1 | J30: 1 | K30: 1 | L30: 1 | M30: 1 | N30: 1 | O30: 1 | P30: 0 | Q30: 0 | R30: 0 | S30: 0 | T30: 0 | U30: 0 | V30: 0 | W30: 0
C31: Thiết kế trường kiểm thử cho đăng xuất | E31: Tuấn | G31: 1 | H31: 1 | I31: 1 | J31: 1 | K31: 1 | L31: 1 | M31: 1 | N31: 1 | O31: 1 | P31: 0 | Q31: 0 | R31: 0 | S31: 0 | T31: 0 | U31: 0 | V31: 0 | W31: 0
C32: Thiết kế trường kiểm thử cho đổi mật khẩu | E32: Toàn | G32: 1 | H32: 1 | I32: 1 | J32: 1 | K32: 1 | L32: 1 | M32: 1 | N32: 1 | O32: 1 | P32: 0 | Q32: 0 | R32: 0 | S32: 0 | T32: 0 | U32: 0 | V32: 0 | W32: 0
C33: Thiết kế trường kiểm thử cho Đăng ký Tài Khoản | E33: Sơn | G33: 1 | H33: 1 | I33: 1 | J33: 1 | K33: 1 | L33: 1 | M33: 1 | N33: 1 | O33: 1 | P33: 0 | Q33: 0 | R33: 0 | S33: 0 | T33: 0 | U33: 0 | V33: 0 | W33: 0
C34: Thiết kế trường kiểm thử cho Tìm Kiếm Khách Sạn | E34: Long | G34: 1 | H34: 1 | I34: 1 | J34: 1 | K34: 1 | L34: 1 | M34: 1 | N34: 1 | O34: 1 | P34: 0 | Q34: 0 | R34: 0 | S34: 0 | T34: 0 | U34: 0 | V34: 0 | W34: 0
C35: Thiết kế trường kiểm thử cho Chi Tiết Khách Sạn | E35: Long | G35: 1 | H35: 1 | I35: 1 | J35: 1 | K35: 1 | L35: 1 | M35: 1 | N35: 1 | O35: 1 | P35: 0 | Q35: 0 | R35: 0 | S35: 0 | T35: 0 | U35: 0 | V35: 0 | W35: 0
C36: Thiết kế trường kiểm thử cho quản lý người dùng | E36: Toàn | G36: 2 | H36: 2 | I36: 2 | J36: 2 | K36: 2 | L36: 2 | M36: 2 | N36: 2 | O36: 2 | P36: 2 | Q36: 0 | R36: 0 | S36: 0 | T36: 0 | U36: 0 | V36: 0 | W36: 0
C37: Thiết kế trường kiểm thử cho quản lý phân quyền | E37: Giỏi | G37: 3 | H37: 2 | I37: 2 | J37: 2 | K37: 2 | L37: 2 | M37: 2 | N37: 2 | O37: 2 | P37: 2 | Q37: 0 | R37: 0 | S37: 0 | T37: 0 | U37: 0 | V37: 0 | W37: 0
Q38: 1
C39: Review all test case of sprint 1 | E39: All team | G39: 8 | H39: 10 | I39: 10 | J39: 10 | K39: 10 | L39: 10 | M39: 10 | N39: 10 | O39: 10 | P39: 10 | Q39: 8 | R39: 0 | S39: 0 | T39: 0 | U39: 0 | V39: 0 | W39: 0
R40: -2
B41: Coding | C41: Thiết kê front-end cho quản lý người dùng | E41: Toàn | G41: 2 | H41: 2 | I41: 2 | J41: 2 | K41: 2 | L41: 2 | M41: 2 | N41: 2 | O41: 2 | P41: 2 | Q41: 2 | R41: 0 | S41: 0 | T41: 0 | U41: 0 | V41: 0 | W41: 0
...

Sheet sprint2
A1: Project name: | C1: Ứng dụng đặt phòng thông minh với AI Search Assistant và gợi ý theo hành vi người dùng | F1: Kết thúc
A2: Module name: | C2: Sprint 2 | F2: Tăng ca
A3: Start date: | C3: 45989 | F3: Muộn
A4: End date: | C4: 46009 | F4: Chậm tiến độ
F5: Trước thời hạn
B6: SPRINT 2 REPORT
B7: No | C7: Thành viên | D7: Thực tế | E7: Ước tính
B8: 1 | C8: Ngô Văn Giỏi | D8: =SUMIF($E$16:$F$97,"Thành",$G$16:$G$97)+SUMIF($E$16:$F$97,"All team",$G$16:$G$97)/5+SUMIF($E$16:$F$97,"Thành,Phương",$G$16:$G$97)/2 -> 8.6 | E8: =SUMIF($E$16:$F$97,"Thành",$H$16:$H$97)+SUMIF($E$16:$F$97,"All team",$H$16:$H$97)/5+SUMIF($E$16:$F$97,"Mạnh,Hoàng",$H$16:$H$97)/2 -> 9.4
B9: 2 | C9: Nguyễn Phước Thanh Tuấn | D9: =SUMIF($E$16:$F$97,"Mạnh",$G$16:$G$97)+SUMIF($E$16:$F$97,"All team",$G$16:$G$97)/5+SUMIF($E$16:$F$97,"Mạnh,Hoàng",$G$16:$G$97)/2+SUMIF($E$16:$F$97,"Mạnh,Lộc,Phương,Hoàng",$G$16:$G$97)/4 -> 8.6 | E9: =SUMIF($E$16:$F$97,"Mạnh",$H$16:$H$97)+SUMIF($E$16:$F$97,"All team",$H$16:$H$97)/5+SUMIF($E$16:$F$97,"Mạnh,Hoàng",$H$16:$H$97)/2+SUMIF($E$16:$F$97,"Mạnh,Lộc,Phương,Hoàng",$H$16:$H$97)/4 -> 9.4
B10: 3 | C10: Nguyễn Ngọc Sơn | D10: =SUMIF($E$16:$F$97,"Phương",$G$16:$G$97)+SUMIF($E$16:$F$97,"All team",$G$16:$G$97)/5+SUMIF($E$16:$F$97,"Thành,Phương",$G$16:$G$97)/2+SUMIF($E$16:$F$97,"Mạnh,Lộc,Phương,Hoàng",$G$16:$G$97)/4 -> 8.6 | E10: =SUMIF($E$16:$F$97,"Phương",$H$16:$H$97)+SUMIF($E$16:$F$97,"All team",$H$16:$H$97)/5+SUMIF($E$16:$F$97,"Thành,Phương",$H$16:$H$97)/2+SUMIF($E$16:$F$97,"Mạnh,Lộc,Phương,Hoàng",$H$16:$H$97)/4 -> 9.4
B11: 4 | C11: Nguyễn Minh Toàn | D11: =SUMIF($E$16:$F$97,"Lộc",$G$16:$G$97)+SUMIF($E$16:$F$97,"All team",$G$16:$G$97)/5+SUMIF($E$16:$F$97,"Mạnh,Lộc,Phương,Hoàng",$G$16:$G$97)/4 -> 8.6 | E11: =SUMIF($E$16:$F$97,"Lộc",$H$16:$H$97)+SUMIF($E$16:$F$97,"All team",$H$16:$H$97)/5+SUMIF($E$16:$F$97,"Mạnh,Lộc,Phương,Hoàng",$H$16:$H$97)/4 -> 9.4
B12: 5 | C12: Nguyễn Thanh Long | D12: =SUMIF($E$16:$F$97,"Hoàng",$G$16:$G$97)+SUMIF($E$16:$F$97,"All team",$G$16:$G$97)/5+SUMIF($E$16:$F$97,"Mạnh,Hoàng",$G$16:$G$97)/2+SUMIF($E$16:$F$97,"Mạnh,Lộc,Phương,Hoàng",$G$16:$G$97)/4 -> 8.6 | E12: =SUMIF($E$16:$F$97,"Hoàng",$H$16:$H$97)+SUMIF($E$16:$F$97,"All team",$H$16:$H$97)/5+SUMIF($E$16:$F$97,"Mạnh,Hoàng",$H$16:$H$97)/2+SUMIF($E$16:$F$97,"Mạnh,Lộc,Phương,Hoàng",$H$16:$H$97)/4 -> 9.4
B13: Tổng | D13: =SUM(D8:D12) -> 43 | E13: =SUM(E8:E12) -> 47
A15: Sprint | B15: Compoment | C15: Task name | E15: Responsible Member | G15: Thực tế | H15: Ước tính | I15: 45985 | J15: 45986 | K15: 45987 | L15: 45988 | M15: 45989 | N15: 45990 | O15: 45991 | P15: 45992 | Q15: 45993 | R15: 45994 | S15: 45995 | T15: 45996 | U15: 45997 | V15: 45998 | W15: 45999 | X15: 46000 | Y15: 46001 | Z15: 46002 | AA15: 46003 | AB15: 46004 | AC15: 46005 | AD15: 46006 | AE15: 46007 | AF15: 46008 | AG15: 46009
A16: Sprint 2 | B16: Họp kế hoạch Sprint | E16: All team | G16: 10 | H16: 10 | I16: 10 | J16: 0 | K16: 0 | L16: 0 | M16: 0 | N16: 0 | O16: 0 | P16: 0 | Q16: 0 | R16: 0 | S16: 0 | T16: 0 | U16: 0 | V16: 0 | W16: 0 | X16: 0 | Y16: 0 | Z16: 0 | AA16: 0 | AB16: 0 | AC16: 0 | AD16: 0 | AE16: 0 | AF16: 0 | AG16: 0
B17: Tạo Sprint Backlog 2 | E17: Tuấn | G17: 2 | H17: 4 | I17: 4 | J17: 2 | K17: 0 | L17: 0 | M17: 0 | N17: 0 | O17: 0 | P17: 0 | Q17: 0 | R17: 0 | S17: 0 | T17: 0 | U17: 0 | V17: 0 | W17: 0 | X17: 0 | Y17: 0 | Z17: 0 | AA17: 0 | AB17: 0 | AC17: 0 | AD17: 0 | AE17: 0 | AF17: 0 | AG17: 0
K18: 2
B19: Tạo tài liệu kiểm thử cho Sprint | E19: All team | G19: 4 | H19: 4 | I19: 4 | J19: 4 | K19: 4 | L19: 0 | M19: 0 | N19: 0 | O19: 0 | P19: 0 | Q19: 0 | R19: 0 | S19: 0 | T19: 0 | U19: 0 | V19: 0 | W19: 0 | X19: 0 | Y19: 0 | Z19: 0 | AA19: 0 | AB19: 0 | AD19: 2 | AE19: 0 | AF19: 0 | AG19: 0
B20: User interface design | C20: Giao diện chức năng “ Hotel Management" | E20: Tuấn | G20: 1 | H20: 1 | I20: 1 | J20: 1 | K20: 1 | L20: 1 | M20: 0 | N20: 0 | O20: 0 | P20: 0 | Q20: 0 | R20: 0 | S20: 0 | T20: 0 | U20: 0 | V20: 0 | W20: 0 | X20: 0 | Y20: 0 | Z20: 0 | AA20: 0 | AB20: 0 | AC20: 0 | AD20: 0 | AE20: 0 | AF20: 0 | AG20: 0
C21: Giao diện chức năng “ Room Management ” | E21: Long | G21: 1 | H21: 1 | I21: 1 | J21: 1 | K21: 1 | L21: 1 | M21: 0 | N21: 0 | O21: 0 | P21: 0 | Q21: 0 | R21: 0 | S21: 0 | T21: 0 | U21: 0 | V21: 0 | W21: 0 | X21: 0 | Y21: 0 | Z21: 0 | AA21: 0 | AB21: 0 | AC21: 0 | AD21: 0 | AE21: 0 | AF21: 0 | AG21: 0
C22: Giao diện Chức năng “Booking” | E22: Tuấn | G22: 1 | H22: 1 | I22: 1 | J22: 1 | K22: 1 | L22: 1 | M22: 0 | N22: 0 | O22: 0 | P22: 0 | Q22: 0 | R22: 0 | S22: 0 | T22: 0 | U22: 0 | V22: 0 | W22: 0 | X22: 0 | Y22: 0 | Z22: 0 | AA22: 0 | AB22: 0 | AC22: 0 | AD22: 0 | AE22: 0 | AF22: 0 | AG22: 0
C23: Giao diện chức năng “ Payment (VNPay) ” | E23: Giỏi | G23: 2 | H23: 2 | I23: 2 | J23: 2 | K23: 2 | L23: 2 | M23: 0 | N23: 0 | O23: 0 | P23: 0 | Q23: 0 | R23: 0 | S23: 0 | T23: 0 | U23: 0 | V23: 0 | W23: 0 | X23: 0 | Y23: 0 | Z23: 0 | AA23: 0 | AB23: 0 | AC23: 0 | AD23: 0 | AE23: 0 | AF23: 0 | AG23: 0
C24: Giao diện chức năng “ Wallet Management” | E24: Giỏi | G24: 1 | H24: 1 | I24: 1 | J24: 1 | K24: 1 | L24: 1 | M24: 1 | N24: 0 | O24: 0 | P24: 0 | Q24: 0 | R24: 0 | S24: 0 | T24: 0 | U24: 0 | V24: 0 | W24: 0 | X24: 0 | Y24: 0 | Z24: 0 | AA24: 0 | AB24: 0 | AC24: 0 | AD24: 0 | AE24: 0 | AF24: 0 | AG24: 0
C25: Giao diện chức năng “ Revenue Management” | E25: Long | G25: 1 | H25: 1 | I25: 1 | J25: 1 | K25: 1 | L25: 1 | M25: 1 | N25: 0 | O25: 0 | P25: 0 | Q25: 0 | R25: 0 | S25: 0 | T25: 0 | U25: 0 | V25: 0 | W25: 0 | X25: 0 | Y25: 0 | Z25: 0 | AA25: 0 | AB25: 0 | AC25: 0 | AD25: 0 | AE25: 0 | AF25: 0 | AG25: 0
C26: Giao diện chức năng “ Admin Dashboard ” | E26: Sơn | G26: 1 | H26: 1 | I26: 1 | J26: 1 | K26: 1 | L26: 1 | M26: 1 | N26: 0
C27: Giao diện chức năng “ Info Pages ” | E27: Long | G27: 2 | H27: 2 | I27: 2 | J27: 2 | K27: 2 | L27: 2 | M27: 2 | N27: 0
C28: Review all user interfaces of sprint 2 | E28: All team | G28: 2 | H28: 2 | I28: 2 | J28: 2 | K28: 2 | L28: 2 | M28: 2 | N28: 0
G29: 5 | H29: 10 | I29: 10 | J29: 10 | K29: 10 | L29: 10 | M29: 10 | N29: 5 | O29: 0 | P29: 0 | Q29: 0 | R29: 0 | S29: 0 | T29: 0 | U29: 0 | V29: 0 | W29: 0 | X29: 0 | Y29: 0 | Z29: 0 | AA29: 0 | AB29: 0 | AC29: 0 | AD29: 0 | AE29: 0 | AF29: 0 | AG29: 0
M30: 1 | O30: 5
B31: Design test case | C31: Thiết kế trường kiểm thử cho “ Hotel Management" | E31: Toàn | G31: 1 | H31: 1 | I31: 1 | J31: 1 | K31: 1 | L31: 1 | M31: 1 | N31: 1 | O31: 1 | P31: 0 | Q31: 0 | R31: 0 | S31: 0 | T31: 0 | U31: 0 | V31: 0 | W31: 0 | X31: 0 | Y31: 0 | Z31: 0 | AA31: 0 | AB31: 0 | AC31: 0 | AD31: 0 | AE31: 0 | AF31: 0 | AG31: 0
C32: Thiết kế trường kiểm thử cho “ Room Management ” | E32: Sơn | G32: 3 | H32: 1 | I32: 1 | J32: 1 | K32: 1 | L32: 1 | M32: 1 | N32: 1 | O32: 1 | P32: 0 | Q32: 0 | R32: 0 | S32: 0 | T32: 0 | U32: 0 | V32: 0 | W32: 0 | X32: 0 | Y32: 0 | Z32: 0 | AA32: 0 | AB32: 0 | AC32: 0 | AD32: 0 | AE32: 0 | AF32: 0 | AG32: 0
P33: 2
C34: Thiết kế trường kiểm thử cho “Booking” | E34: Long | G34: 1 | H34: 1 | I34: 1 | J34: 1 | K34: 1 | L34: 1 | M34: 1 | N34: 1 | O34: 1 | P34: 0 | Q34: 0 | R34: 0 | S34: 0 | T34: 0 | U34: 0 | V34: 0 | W34: 0 | X34: 0 | Y34: 0 | Z34: 0 | AA34: 0 | AB34: 0 | AC34: 0 | AD34: 0 | AE34: 0 | AF34: 0 | AG34: 0
C35: Thiết kế trường kiểm thử cho “ Payment (VNPay) ” | E35: Sơn | G35: 1 | H35: 1 | I35: 1 | J35: 1 | K35: 1 | L35: 1 | M35: 1 | N35: 1 | O35: 1 | P35: 0 | Q35: 0 | R35: 0 | S35: 0 | T35: 0 | U35: 0 | V35: 0 | W35: 0 | X35: 0 | Y35: 0 | Z35: 0 | AA35: 0 | AB35: 0 | AC35: 0 | AD35: 0 | AE35: 0 | AF35: 0 | AG35: 0
C36: Thiết kế trường kiểm thử cho “ Wallet Management” | E36: Giỏi | G36: 1 | H36: 1 | I36: 1 | J36: 1 | K36: 1 | L36: 1 | M36: 1 | N36: 1 | O36: 1 | P36: 1 | Q36: 0 | R36: 0 | S36: 0 | T36: 0 | U36: 0 | V36: 0 | W36: 0 | X36: 0 | Y36: 0 | Z36: 0 | AA36: 0 | AB36: 0 | AC36: 0 | AD36: 0 | AE36: 0 | AF36: 0 | AG36: 0
C37: Thiết kế trường kiểm thử cho “ Revenue Management” | E37: Tuấn | G37: 1 | H37: 1 | I37: 1 | J37: 1 | K37: 1 | L37: 1 | M37: 1 | N37: 1 | O37: 1 | P37: 1 | Q37: 0 | R37: 0 | S37: 0 | T37: 0 | U37: 0 | V37: 0 | W37: 0 | X37: 0 | Y37: 0 | Z37: 0 | AA37: 0 | AB37: 0 | AC37: 0 | AD37: 0 | AE37: 0 | AF37: 0 | AG37: 0
C38: Thiết kế trường kiểm thử cho “ Admin Dashboard ” | E38: Toàn | G38: 1 | H38: 1 | I38: 1 | J38: 1 | K38: 1 | L38: 1 | M38: 1 | N38: 1 | O38: 1 | P38: 1 | Q38: 0 | R38: 0 | S38: 0 | T38: 0 | U38: 0 | V38: 0 | W38: 0 | X38: 0 | Y38: 0 | Z38: 0 | AA38: 0 | AB38: 0 | AC38: 0 | AD38: 0 | AE38: 0 | AF38: 0 | AG38: 0
C39: Thiết kế trường kiểm thử cho “ Info Pages ” | E39: Long | G39: 1 | H39: 1 | I39: 1 | J39: 1 | K39: 1 | L39: 1 | M39: 1 | N39: 1 | O39: 1 | P39: 1 | Q39: 0 | R39: 0 | S39: 0 | T39: 0 | U39: 0 | V39: 0 | W39: 0 | X39: 0 | Y39: 0 | Z39: 0 | AA39: 0 | AB39: 0 | AC39: 0 | AD39: 0 | AE39: 0 | AF39: 0 | AG39: 0
G40: 1 | H40: 1 | I40: 1 | J40: 1 | K40: 1 | L40: 1 | M40: 1 | N40: 1 | O40: 1 | P40: 1 | Q40: 0 | R40: 0 | S40: 0 | T40: 0 | U40: 0 | V40: 0 | W40: 0 | X40: 0 | Y40: 0 | Z40: 0 | AA40: 0 | AB40: 0 | AC40: 0 | AD40: 0 | AE40: 0 | AF40: 0 | AG40: 0
C41: Review all test case of sprint 2 | E41: All team | G41: 7 | H41: 10 | I41: 10 | J41: 10 | K41: 10 | L41: 10 | M41: 10 | N41: 10 | O41: 10 | P41: 10 | Q41: 7 | R41: 0 | S41: 0 | T41: 0 | U41: 0 | V41: 0 | W41: 0 | X41: 0 | Y41: 0 | Z41: 0 | AA41: 0 | AB41: 0 | AC41: 0 | AD41: 0 | AE41: 0 | AF41: 0 | AG41: 0
...

Sheet Total
A1: SPRINT BACKLOG REPORT
B2: Giỏi | D2: Tuấn | F2: Sơn | H2: Toàn | J2: Long
B3: Thực tế | C3: Ước tính | D3: Thực tế | E3: Ước tính | F3: Thực tế | G3: Ước tính | H3: Thực tế | I3: Ước tính | J3: Thực tế | K3: Ước tính
A4: Sprint 1 | B4: 10.8 | C4: ='Sprint 1'!$E$8 -> 11.6 | D4: ='Sprint 1'!$D$9 -> 10.8 | E4: ='Sprint 1'!$E$9 -> 11.6 | F4: ='Sprint 1'!$D$10 -> 10.8 | G4: ='Sprint 1'!$E$10 -> 11.6 | H4: ='Sprint 1'!$D$11 -> 10.8 | I4: ='Sprint 1'!$E$11 -> 11.6 | J4: ='Sprint 1'!$D$12 -> 10.8 | K4: ='Sprint 1'!$E$12 -> 11.6
A5: Sprint 2 | B5: 8.6 | C5: 9.4 | D5: 9.6 | E5: 10.4 | F5: 8.6 | G5: 9.4 | H5: 8.6 | I5: 9.4 | J5: 8.6 | K5: 9.4
A7: Tổng | B7: =SUM(B4:B6) -> 19.4 | C7: =SUM(C4:C6) -> 21 | D7: =SUM(D4:D6) -> 20.4 | E7: =SUM(E4:E6) -> 22 | F7: =SUM(F4:F6) -> 19.4 | G7: =SUM(G4:G6) -> 21 | H7: =SUM(H4:H6) -> 19.4 | I7: =SUM(I4:I6) -> 21 | ... K7: =SUM(K4:K6) -> 21
E10: FINAL TOTAL
E11: Thực tế | F11: =SUMIF($B$3:$K$3,"Thực tế",$B$7:$K$7) -> 98
E12: Ước tính | F12: =SUMIF($B$3:$K$3,"Ước tính",$B$7:$K$7) -> 106
